#VRML_SIM R2025a utf8

EXTERNPROTO "https://raw.githubusercontent.com/cyberbotics/webots/R2025a/projects/objects/backgrounds/protos/TexturedBackground.proto"
EXTERNPROTO "https://raw.githubusercontent.com/cyberbotics/webots/R2025a/projects/objects/backgrounds/protos/TexturedBackgroundLight.proto"
EXTERNPROTO "https://raw.githubusercontent.com/cyberbotics/webots/R2023b/projects/objects/floors/protos/Floor.proto"

WorldInfo {
  info [
    "SAHR - Best Implementation Based on Paper"
  ]
  basicTimeStep 1
  contactProperties [
    ContactProperties {
    }
    ContactProperties {
      material1 "mat1"
      material2 "mat2"
      coulombFriction [
        0.8
      ]
      frictionRotation 1 1
    }
  ]
}
Viewpoint {
  orientation -0.16383297163068428 0.053151131703809515 0.985055183533016 2.48806832666231
  position 0.9419421409006026 -0.3649770888220834 0.36095099876242254
}
TexturedBackground {
}
TexturedBackgroundLight {
}
Solid {
  translation -0.002548526877844466 -0.00040269308659803194 0.15377934653861047
  rotation 0 0 1 0.0013296062847445635
  children [
    Pose {
      translation 0 0 0.1
      children [
        Robot {
          translation 0 0 -0.05
          children [
            HingeJoint {
              jointParameters HingeJointParameters {
                position 0.327
                axis 0 0 1
                minStop -3.14
                maxStop 3.14
              }
              device [
                PositionSensor {
                  name "arm_angle_sensor"
                }
              ]
              endPoint DEF x Solid {
                translation 0.03410969823619173 1.0969348973604784e-05 -0.0038018000000005162
                rotation -0.00016107592521574917 0.9999999740558929 0.00016106756281038362 1.570848270008141
                children [
                  Solid {
                    translation -4.89665e-14 0 -0.025
                    rotation 0 1 0 1.5708
                    children [
                      Shape {
                        appearance PBRAppearance {
                        }
                        geometry Cylinder {
                          height 0.01
                          radius 0.024
                        }
                      }
                    ]
                    name "solid(1)"
                    boundingObject Cylinder {
                      height 0.01
                      radius 0.024
                    }
                  }
                  HingeJoint {
                    jointParameters HingeJointParameters {
                      position 2.545451275482914
                      axis 0 1 0
                      minStop -3.14
                      maxStop 3.14
                    }
                    endPoint Solid {
                      translation 0.004795900000000061 -0.00259366 0.19499200000000022
                      rotation 0 1 0 0
                      children [
                        Solid {
                          translation 0 0 0.2
                          children [
                            Shape {
                              appearance PBRAppearance {
                              }
                              geometry Cylinder {
                                height 0.02
                                radius 0.013
                              }
                            }
                          ]
                          name "solid(1)"
                          boundingObject Cylinder {
                            height 0.02
                            radius 0.013
                          }
                        }
                        HingeJoint {
                          jointParameters HingeJointParameters {
                            axis 0 0 1
                          }
                          device [
                            RotationalMotor {
                              name "hip_motor"
                              minPosition -3.14
                              maxPosition 3.14
                              maxTorque 100
                            }
                            PositionSensor {
                              name "hip_sensor"
                            }
                          ]
                          endPoint Solid {
                            translation 0.0299715 -0.000230235 0.220012
                            rotation 0.011524482315039738 0.9999333396793559 0.0007088759129188692 1.5700604538172254
                            children [
                              Solid {
                                translation -0.015 0 -0.03
                                rotation 0 1 0 1.5708
                                children [
                                  Shape {
                                    appearance PBRAppearance {
                                    }
                                    geometry Cylinder {
                                      height 0.01
                                      radius 0.014
                                    }
                                  }
                                ]
                                name "solid(2)"
                                boundingObject Cylinder {
                                  height 0.01
                                  radius 0.014
                                }
                              }
                              DistanceSensor {
                                translation 0 0 0.208
                                name "height_sensor"
                                lookupTable [
                                  0 0 0
                                  1 1 0
                                ]
                                type "laser"
                              }
                              InertialUnit {
                                name "inertial_unit"
                              }
                              GPS {
                                name "body_gps"
                              }
                              HingeJoint {
                                jointParameters HingeJointParameters {
                                }
                                device [
                                  PositionSensor {
                                    name "centrifugal_sensor"
                                  }
                                  RotationalMotor {
                                    name "centrifugal_motor"
                                    maxVelocity 100
                                    minPosition -6.28
                                    maxPosition 19.3139
                                    maxTorque 100
                                  }
                                ]
                                endPoint Solid {
                                  translation -0.0250001 0.000704763 0.0095311
                                  rotation 0.9999999999966966 2.568149999991517e-06 -1.066569999996477e-07 0.009995307179593384
                                  children [
                                    Solid {
                                      translation 0 0 0.08
                                      children [
                                        Shape {
                                          appearance Appearance {
                                            material Material {
                                            }
                                          }
                                          geometry Sphere {
                                            radius 0.01
                                          }
                                        }
                                      ]
                                      boundingObject Sphere {
                                        radius 0.01
                                      }
                                      physics Physics {
                                        mass 2
                                      }
                                    }
                                    Shape {
                                      appearance Appearance {
                                        material Material {
                                          diffuseColor 0.607843 0.607843 0.607843
                                        }
                                      }
                                      geometry Cylinder {
                                        height 0.15
                                        radius 0.005
                                      }
                                    }
                                  ]
                                  name "solid(1)"
                                  boundingObject Cylinder {
                                    height 0.15
                                    radius 0.005
                                  }
                                  physics Physics {
                                    mass 0.1
                                  }
                                }
                              }
                              SliderJoint {
                                jointParameters JointParameters {
                                  position -0.002646144835211221
                                  minStop -0.1
                                  maxStop 0.1
                                  springConstant 50000
                                }
                                device [
                                  PositionSensor {
                                    name "leg_sensor"
                                  }
                                ]
                                endPoint Solid {
                                  translation 0 0 0.137354
                                  children [
                                    TouchSensor {
                                      translation 1.6352324477275637e-06 -1.165395607460873e-06 0.0003849451531805076
                                      rotation -0.01633208755444823 0.9998665384044335 0.0004102380400166768 3.5206124051200952e-09
                                      name "foot_sensor"
                                      boundingObject Sphere {
                                        radius 0.01
                                      }
                                    }
                                    Pose {
                                      translation 0 0 -0.05
                                      children [
                                        Shape {
                                          appearance Appearance {
                                            material Material {
                                              diffuseColor 0.1 0.1 0.1
                                            }
                                          }
                                          geometry Cylinder {
                                            height 0.1
                                            radius 0.005
                                          }
                                        }
                                      ]
                                    }
                                    Shape {
                                      appearance Appearance {
                                        material Material {
                                          diffuseColor 0.2 0.4 0.8
                                        }
                                      }
                                      geometry Sphere {
                                        radius 0.01
                                      }
                                    }
                                  ]
                                  contactMaterial "mat1"
                                  boundingObject Sphere {
                                    radius 0.01
                                  }
                                  physics Physics {
                                    density -1
                                    mass 0.1
                                  }
                                }
                              }
                              Pose {
                                children [
                                  Shape {
                                    appearance Appearance {
                                      material Material {
                                        diffuseColor 0.6 0.6 0.6
                                      }
                                    }
                                    geometry Box {
                                      size 0.02 0.02 0.1
                                    }
                                  }
                                ]
                              }
                            ]
                            boundingObject Box {
                              size 0.02 0.02 0.1
                            }
                            physics Physics {
                              density -1
                              mass 10
                              centerOfMass [
                                0 0 0
                              ]
                            }
                          }
                        }
                        Shape {
                          appearance Appearance {
                            material Material {
                              diffuseColor 0.3 0.3 0.3
                            }
                          }
                          geometry Cylinder {
                            height 0.4
                            radius 0.01
                          }
                        }
                      ]
                      contactMaterial "mat1"
                      boundingObject Cylinder {
                        height 0.4
                        radius 0.01
                      }
                      physics Physics {
                        density -1
                        mass 0.001
                        centerOfMass [
                          0 0 0
                        ]
                        inertiaMatrix [
                          1 1 1
                          0 0 0
                        ]
                      }
                    }
                  }
                  Pose {
                    translation 0 0 -0.0125
                    children [
                      Shape {
                        appearance PBRAppearance {
                        }
                        geometry Cylinder {
                          height 0.02
                          radius 0.01
                        }
                      }
                    ]
                  }
                ]
                boundingObject Box {
                  size 0.1 0.1 0.1
                }
                physics Physics {
                  density -1
                  mass 0.001
                }
              }
            }
          ]
          boundingObject Box {
            size 0.1 0.1 0.1
          }
          physics Physics {
            density -1
            mass 0.001
          }
          controller "sahr_jump_controller"
        }
      ]
    }
    Pose {
      translation 0 0 0.1
    }
    Shape {
      appearance Appearance {
        material Material {
          diffuseColor 0.5 0.5 0.5
        }
      }
      geometry Cylinder {
        height 0.3
        radius 0.01
      }
    }
  ]
  boundingObject Pose {
    translation 0 0 -0.15
    children [
      Box {
        size 0.5 0.5 0.01
      }
    ]
  }
  physics Physics {
    density -1
    mass 100
  }
}
Floor {
  contactMaterial "mat2"
  size 2 2
}
