#VRML_SIM R2025a utf8

EXTERNPROTO "https://raw.githubusercontent.com/cyberbotics/webots/R2025a/projects/objects/backgrounds/protos/TexturedBackground.proto"
EXTERNPROTO "https://raw.githubusercontent.com/cyberbotics/webots/R2025a/projects/objects/backgrounds/protos/TexturedBackgroundLight.proto"
EXTERNPROTO "https://raw.githubusercontent.com/cyberbotics/webots/R2023b/projects/objects/floors/protos/Floor.proto"

WorldInfo {
  info [
    "SAHR - Best Implementation Based on Paper"
  ]
  basicTimeStep 1
  contactProperties [
    ContactProperties {
    }
    ContactProperties {
      material1 "mat1"
      material2 "mat2"
      coulombFriction [
        0.8
      ]
      frictionRotation 1 1
    }
  ]
}
Viewpoint {
  orientation 0.38027875533931 0.0007536173669493107 -0.9248716128730785 3.1528722729186436
  position 1.8809792576150897 0.016989150025310373 1.8944421246813345
}
TexturedBackground {
}
TexturedBackgroundLight {
}
Solid {
  translation 0 0 0.155
  children [
    Pose {
      translation 0 0 0.1
      children [
        Robot {
          children [
            HingeJoint {
              jointParameters HingeJointParameters {
                position 0.3
                axis 0 0 1
                minStop -3.14
                maxStop 3.14
              }
              endPoint DEF x Solid {
                translation 0.02379495386220642 0.00735494199240232 -9.631652412589334e-05
                rotation -0.1477926112861902 0.9778951382444514 0.14791363239091324 1.5923530890393824
                children [
                  HingeJoint {
                    jointParameters HingeJointParameters {
                      position -1.1
                      axis 0 1 0
                      minStop -3.14
                      maxStop 3.14
                    }
                    endPoint Solid {
                      translation -0.19606652514361603 7.591549631122516e-08 0.09979191745962386
                      rotation -7.836666933782711e-08 -0.999999999999992 1.0056662110862309e-07 1.100000000000013
                      children [
                        HingeJoint {
                          jointParameters HingeJointParameters {
                            axis 0 0 1
                          }
                          device [
                            RotationalMotor {
                              name "hip_motor"
                              acceleration 1000
                              maxVelocity 30
                              minPosition -1.57
                              maxPosition 1.57
                            }
                            PositionSensor {
                              name "hip_sensor"
                            }
                          ]
                          endPoint Solid {
                            translation -2.9700664968873646e-06 7.825013078848857e-08 0.20000406072197416
                            rotation -1.3788200343981934e-05 0.9999999998099618 1.3782665742376115e-05 1.570000025062598
                            children [
                              SliderJoint {
                                jointParameters JointParameters {
                                  minStop -0.1
                                  maxStop 0.1
                                  springConstant 50000
                                }
                                device [
                                  PositionSensor {
                                    name "leg_sensor"
                                  }
                                ]
                                endPoint Solid {
                                  translation 0.00030704767281952705 1.0035567441203652e-05 0.2003026618351411
                                  rotation -0.6511612934458448 0.7589344860847103 0.00272318733675352 2.347411812071907e-06
                                  children [
                                    TouchSensor {
                                      name "foot_sensor"
                                    }
                                    Pose {
                                      translation 0 0 -0.05
                                      children [
                                        Shape {
                                          appearance Appearance {
                                            material Material {
                                              diffuseColor 0.1 0.1 0.1
                                            }
                                          }
                                          geometry Cylinder {
                                            height 0.1
                                            radius 0.005
                                          }
                                        }
                                      ]
                                    }
                                    Shape {
                                      appearance Appearance {
                                        material Material {
                                          diffuseColor 0.2 0.4 0.8
                                        }
                                      }
                                      geometry Sphere {
                                        radius 0.01
                                      }
                                    }
                                  ]
                                  contactMaterial "mat1"
                                  boundingObject Sphere {
                                    radius 0.01
                                  }
                                  physics Physics {
                                    density -1
                                    mass 0.1
                                  }
                                }
                              }
                              Pose {
                                translation 0 0 0.05
                                children [
                                  Shape {
                                    appearance Appearance {
                                      material Material {
                                        diffuseColor 0.6 0.6 0.6
                                      }
                                    }
                                    geometry Box {
                                      size 0.02 0.02 0.1
                                    }
                                  }
                                ]
                              }
                            ]
                            boundingObject Box {
                              size 0.02 0.02 0.2
                            }
                            physics Physics {
                              density -1
                              mass 10
                              centerOfMass [
                                0 0 0
                              ]
                            }
                          }
                        }
                        Shape {
                          appearance Appearance {
                            material Material {
                              diffuseColor 0.3 0.3 0.3
                            }
                          }
                          geometry Cylinder {
                            height 0.4
                            radius 0.01
                          }
                        }
                      ]
                      contactMaterial "mat1"
                      boundingObject Cylinder {
                        height 0.4
                        radius 0.01
                      }
                      physics Physics {
                        density -1
                        mass 0.001
                        centerOfMass [
                          0 0 0
                        ]
                        inertiaMatrix [
                          1 1 1
                          0 0 0
                        ]
                      }
                    }
                  }
                  Pose {
                    translation 0 0 -0.0125
                    children [
                      Shape {
                        appearance Appearance {
                          material Material {
                            diffuseColor 0.4 0.4 0.4
                          }
                        }
                        geometry Cylinder {
                          height 0.02
                          radius 0.01
                        }
                      }
                    ]
                  }
                ]
                boundingObject Box {
                  size 0.1 0.1 0.1
                }
                physics Physics {
                  density -1
                  mass 0.001
                }
              }
            }
          ]
          boundingObject Box {
            size 0.1 0.1 0.1
          }
          physics Physics {
            density -1
            mass 0.001
          }
          controller "sahr_jump_controller"
        }
      ]
    }
    Pose {
      translation 0 0 0.1
    }
    Shape {
      appearance Appearance {
        material Material {
          diffuseColor 0.5 0.5 0.5
        }
      }
      geometry Cylinder {
        height 0.2
        radius 0.01
      }
    }
  ]
  boundingObject Pose {
    translation 0 0 -0.15
    children [
      Box {
        size 0.5 0.5 0.01
      }
    ]
  }
  physics Physics {
    density -1
    mass 100
  }
}
Floor {
  contactMaterial "mat2"
  size 2 2
}
